Workbook

Sheet 🏠 Home
B2: Better Juice
B3: Fuel Your Better.
B4: Lean Tracker · ทำน้อยได้มาก · Updated 20 May 2026
B6: 📅 Key Dates | E6: 💡 ทำน้อยได้มาก
B7: 🚀 Soft Open | C7: 13 พ.ค. 2026 | D7: Day 1 — invite-only | E7: • ทุกเช้า (5 นาที): เปิด This Week — เช็คงานที่ต้องทำ
B8: 🎉 Grand Open | C8: 28 พ.ค. 2026 | D8: Public + Marketing push | E8: • ทุกเย็นปิดร้าน (3 นาที): กรอก Daily Log — แค่ 8 ช่อง
B9: Soft Period | C9: 13-27 พ.ค. | D9: 3 สัปดาห์ iterate | E9: • ทุกจันทร์ (10 นาที): ดู Home dashboard — ปรับ This Week
E10: • ทุกเดือน (30 นาที): ดู P&L แยก, update Suppliers scorecard
B11: 📊 Snapshot (auto from Daily Log) | E11: • ไฟล์อื่น (Recipe Book) เปิดเมื่อต้องการสูตร — ไม่ใช่ทุกวัน
B12: ลูกค้ารวม (7 วันล่าสุด) | C12: =IFERROR(SUM(OFFSET('📅 Daily'!B2,COUNTA('📅 Daily'!A:A)-8,0,7,1)),0)
B13: Revenue 7 วัน ฿ | C13: =IFERROR(SUM(OFFSET('📅 Daily'!D2,COUNTA('📅 Daily'!A:A)-8,0,7,1)),0)
B14: Avg ticket ฿ | C14: =IFERROR(B13/B12,0)
B15: Waste % avg | C15: =IFERROR(AVERAGE(OFFSET('📅 Daily'!G2,COUNTA('📅 Daily'!A:A)-8,0,7,1)),0)
B16: New members 7 วัน | C16: =IFERROR(SUM(OFFSET('📅 Daily'!H2,COUNTA('📅 Daily'!A:A)-8,0,7,1)),0)
B17: Complaints 7 วัน | C17: =IFERROR(SUM(OFFSET('📅 Daily'!I2,COUNTA('📅 Daily'!A:A)-8,0,7,1)),0)
B19: 🎯 Targets
B20: Break-even/วัน | C20: 42 คน
B21: เป้าเดือน 1 | C21: 140-180/วัน
B22: เป้าเดือน 6 | C22: 220-280/วัน
B23: Avg ticket | C23: 120 ฿
B24: Waste target | C24: ≤ 5%
B25: NPS | C25: ≥ 60
B28: 📂 ชีตในไฟล์นี้
B29: 📅 Daily | C29: กรอกตอนปิดร้านทุกวัน (3 นาที)
B30: 🥤 Menu | C30: 26 SKU + ราคา + ต้นทุน · reference
B31: ✅ This Week | C31: งานสัปดาห์นี้ · เช็คทุกเช้า
B32: 👥 Team | C32: พนักงาน + กะ · update เดือนละ 1
B33: 🛒 Suppliers | C33: ผู้ขาย + scorecard · review รายเดือน

Sheet 📅 Daily
A1: วันที่ | B1: ลูกค้า | C1: Trans. | D1: Revenue ฿ | E1: Avg ticket ฿ | F1: Top SKU | G1: Waste % | H1: New mem. | I1: Complaints | J1: หมายเหตุ | L1: 💡 กรอกตอนปิดร้านทุกวัน — แค่ 8 ช่อง (3 นาที)
A2: 2026-05-12 | E2: =IFERROR(D2/C2,0)
A3: 2026-05-13 | E3: =IFERROR(D3/C3,0) | J3: 🚀 SOFT OPEN DAY 1
A4: 2026-05-14 | E4: =IFERROR(D4/C4,0)
A5: 2026-05-15 | E5: =IFERROR(D5/C5,0)
A6: 2026-05-16 | E6: =IFERROR(D6/C6,0)
A7: 2026-05-17 | E7: =IFERROR(D7/C7,0)
A8: 2026-05-18 | E8: =IFERROR(D8/C8,0)
A9: 2026-05-19 | E9: =IFERROR(D9/C9,0)
A10: 2026-05-20 | E10: =IFERROR(D10/C10,0)
A11: 2026-05-21 | E11: =IFERROR(D11/C11,0)
A12: 2026-05-22 | E12: =IFERROR(D12/C12,0)
A13: 2026-05-23 | E13: =IFERROR(D13/C13,0)
A14: 2026-05-24 | E14: =IFERROR(D14/C14,0)
A15: 2026-05-25 | E15: =IFERROR(D15/C15,0)
... A17: 2026-05-27 | E17: =IFERROR(D17/C17,0)
A18: 2026-05-28 | E18: =IFERROR(D18/C18,0) | J18: 🎉 GRAND OPEN
A19: 2026-05-29 | E19: =IFERROR(D19/C19,0)
A20: 2026-05-30 | E20: =IFERROR(D20/C20,0)
A21: 2026-05-31 | E21: =IFERROR(D21/C21,0)
A22: 2026-06-01 | E22: =IFERROR(D22/C22,0)
A23: 2026-06-02 | E23: =IFERROR(D23/C23,0)
A24: 2026-06-03 | E24: =IFERROR(D24/C24,0)
A25: 2026-06-04 | E25: =IFERROR(D25/C25,0)
A26: 2026-06-05 | E26: =IFERROR(D26/C26,0)
A27: 2026-06-06 | E27: =IFERROR(D27/C27,0)
A28: 2026-06-07 | E28: =IFERROR(D28/C28,0)
A29: 2026-06-08 | E29: =IFERROR(D29/C29,0)
A30: 2026-06-09 | E30: =IFERROR(D30/C30,0)
... A61: 2026-07-10 | E61: =IFERROR(D61/C61,0)
A62: TOTAL | B62: =SUM(B2:B61) | C62: =SUM(C2:C61) | D62: =SUM(D2:D61) | E62: =IFERROR(D62/C62,0) | H62: =SUM(H2:H61) | I62: =SUM(I2:I61)

Sheet 📊 Sales Forecast
A1: 📊 BETTER JUICE — SALES FORECAST (2-WEEK LAUNCH)
A2: Grand Open 28 พ.ค. 2026 · Conservative ramp-up model · Assumptions: Avg ticket ฿98-108 · Cold-press 40% / Smoothie 35% / Wrap 15% / Add-ons 10%
A3: วันที่ | B3: วัน | C3: ลูกค้า (คน) | D3: Revenue ฿ | E3: Avg Ticket ฿ | F3: Cold-press ฿ | G3: Smoothie ฿ | H3: Wrap ฿ | I3: GP ฿ (~68%) | J3: หมายเหตุ
A4: ⬛ WEEK 1 — Grand Open Week (28 พ.ค. – 3 มิ.ย. 2026)
A5: 28 May 26 | B5: Thu | C5: 45 | D5: 4590 | E5: 102 | F5: 1836 | G5: 1606 | H5: 688 | I5: 3121 | J5: 🎉 GRAND OPEN — walk-in surge
A6: 29 May 26 | B6: Fri | C6: 38 | D6: 3800 | E6: 100 | F6: 1520 | G6: 1330 | H6: 570 | I6: 2584 | J6: Post-opening buzz
A7: 30 May 26 | B7: Sat | C7: 60 | D7: 6300 | E7: 105 | F7: 2520 | G7: 2205 | H7: 945 | I7: 4284 | J7: Weekend peak
A8: 31 May 26 | B8: Sun | C8: 55 | D8: 5720 | E8: 104 | F8: 2288 | G8: 2002 | H8: 858 | I8: 3890 | J8: Weekend — family + tourist
A9: 01 Jun 26 | B9: Mon | C9: 30 | D9: 2940 | E9: 98 | F9: 1176 | G9: 1029 | H9: 441 | I9: 1999 | J9: Weekday dip
A10: 02 Jun 26 | B10: Tue | C10: 32 | D10: 3136 | E10: 98 | F10: 1254 | G10: 1098 | H10: 470 | I10: 2132 | J10: Weekday
A11: 03 Jun 26 | B11: Wed | C11: 35 | D11: 3465 | E11: 99 | F11: 1386 | G11: 1213 | H11: 520 | I11: 2356 | J11: Mid-week pickup
A12: WEEK 1 TOTAL
A13: ⬛ WEEK 2 — Building Momentum (4 – 10 มิ.ย. 2026)
A14: 04 Jun 26 | B14: Thu | C14: 40 | D14: 4000 | E14: 100 | F14: 1600 | G14: 1400 | H14: 600 | I14: 2720 | J14: Wk2 — growing regulars
A15: 05 Jun 26 | B15: Fri | C15: 48 | D15: 4944 | E15: 103 | F15: 1978 | G15: 1730 | H15: 742 | I15: 3362 | J15: Pre-weekend surge
A16: 06 Jun 26 | B16: Sat | C16: 70 | D16: 7560 | E16: 108 | F16: 3024 | G16: 2646 | H16: 1134 | I16: 5141 | J16: Weekend peak wk2
A17: 07 Jun 26 | B17: Sun | C17: 65 | D17: 6890 | E17: 106 | F17: 2756 | G17: 2412 | H17: 1034 | I17: 4685 | J17: Weekend tourist + family
A18: 08 Jun 26 | B18: Mon | C18: 42 | D18: 4200 | E18: 100 | F18: 1680 | G18: 1470 | H18: 630 | I18: 2856 | J18: Regulars established
A19: 09 Jun 26 | B19: Tue | C19: 45 | D19: 4545 | E19: 101 | F19: 1818 | G19: 1591 | H19: 682 | I19: 3091 | J19: Growing office crowd
A20: 10 Jun 26 | B20: Wed | C20: 48 | D20: 4896 | E20: 102 | F20: 1958 | G20: 1714 | H20: 734 | I20: 3329 | J20: Strong mid-week
A21: WEEK 2 TOTAL | C21: 358 | D21: 37035 | E21: 103 | F21: 14814 | G21: 12962 | H21: 5555 | I21: 25184
A22: 🏆 2-WEEK GRAND TOTAL | C22: 653 | D22: 66986 | E22: 103 | F22: 26794 | G22: 23445 | H22: 10048 | I22: 45550
A24: 📌 ASSUMPTIONS & NOTES
A25: • Model based on conservative ramp-up for new juice bar in Thai market (no historical data yet — update Daily tab nightly to replace forecast)
A26: • Week 1 avg 42 customers/day | Week 2 avg 51 customers/day → expected ~20% week-over-week growth as word spreads
A27: • Revenue mix: Cold-press 40% · Smoothie 35% · Wrap 15% · Add-ons 10% | GP margin ~68% (after food cost ~32%)
A28: • Weekend (Sat/Sun) modelled at +60% vs. weekday — adjust if location skews toward office crowd
A29: • Top SKUs: SMILE ON + KEEP RISING (morning best-sellers) · FULL POWER + GLOW UP (weekend/fitness) · THINK SHARP (office)
A30: • Grand Open day (28 พ.ค.) includes launch boost — may normalise Day 2-3; re-forecast after first week of actuals

Sheet 🥤 Menu
A1: # | B1: Menu Name | C1: Mantra/Long Form | D1: Type | E1: Size | F1: ส่วนผสมหลัก | G1: ราคา ฿ | H1: ต้นทุน ฿ | I1: Margin % | J1: Persona | K1: Daypart
A2: 1 | B2: KEEP RISING | C2: BLOOMING CONFIDENCE | D2: Cold-press | E2: 12oz | F2: Apple 225g + Carrot 96g + Ginger 3g + Lime + Sea Salt | G2: 98 | H2: 32 | I2: =IFERROR((G2-H2)/G2,0) | J2: Office Nut, Tourist | K2: Morning
A3: 2 | B3: MIND CLEAR | C3: CRYSTAL CLARITY | D3: Cold-press | E3: 12oz | F3: Pineapple 168g + Cucumber 144g + Celery 24g + Kale 20g + Lime + Ginger 2.4g | G3: 98 | H3: 30 | I3: =IFERROR((G3-H3)/G3,0) | J3: Office Nut | K3: Morning-Mid
A4: 3 | B4: SMILE ON | C4: RADIANT VITALITY | D4: Cold-press | E4: 12oz | F4: Orange 245g + Passion Fruit 55g + Carrot 75g + Celery 30g + Sea Salt | G4: 98 | H4: 30 | I4: =IFERROR((G4-H4)/G4,0) | J4: All | K4: All day
A5: 4 | B5: FULL POWER | C5: VIBRANT HYDRATION | D5: Cold-press | E5: 12oz | F5: Watermelon 190g + Pineapple 75g + Passion Fruit 30g + Lime + Sea Salt | G5: 88 | H5: 26 | I5: =IFERROR((G5-H5)/G5,0) | J5: Fitness, Family | K5: Post-workout
A6: 5 | B6: KEEP GOING | C6: PASSIONATE FUEL | D6: Cold-press | E6: 12oz | F6: Apple 180g + Carrot 220g + Lemon 24g + Beetroot 18g | G6: 98 | H6: 30 | I6: =IFERROR((G6-H6)/G6,0) | J6: Office Nut | K6: All day
A7: 6 | B7: RESET DAY | C7: RESTART RHYTHM | D7: Cold-press | E7: 12oz | F7: Green Apple 200g + Celery 45g + Pineapple 90g + Sweet Basil + Lime | G7: 88 | H7: 28 | I7: =IFERROR((G7-H7)/G7,0) | J7: Wellness Mom | K7: Morning/Sunday
A8: 7 | B8: STAY SHARP | C8: PURE AMBITION | D8: Cold-press | E8: 12oz | F8: Cucumber 140g + Celery 18g + Kale 8g + Lemon 7g + Green Apple 140g + Mint | G8: 98 | H8: 30 | I8: =IFERROR((G8-H8)/G8,0) | J8: Office Nut | K8: Morning-Mid
A9: 8 | B9: EASY FLOW | C9: SMOOTH ASCENT | D9: Cold-press | E9: 12oz | F9: Guava 165g + Red Apple 100g + Green Apple 44g + Lime + Sea Salt | G9: 88 | H9: 26 | I9: =IFERROR((G9-H9)/G9,0) | J9: Mom, Wellness | K9: All day
A10: 9 | B10: SHINE BRIGHT | C10: GLOW UP CRYSTAL | D10: Cold-press | E10: 12oz | F10: Beetroot 50g + Pineapple 110g + Orange 160g + Red Apple 90g + Ginger 5g | G10: 98 | H10: 28 | I10: =IFERROR((G10-H10)/G10,0) | J10: Wellness Mom | K10: All day
A11: 10 | B11: STAND PROUD | C11: ANCIENT ANTIOXIDANT | D11: Cold-press Premium | E11: 12oz | F11: Pomegranate 180g + Green Apple 80g + Carrot 50g + Lemon + Mint | G11: 138 | H11: 41 | I11: =IFERROR((G11-H11)/G11,0) | J11: Premium | K11: Afternoon
A12: 11 | B12: FEEL GOOD | C12: DAILY COMFORT | D12: Smoothie | E12: 16oz | F12: Strawberry 40g + Banana 50g + Apple juice 100ml + Yogurt 15g + Date | G12: 88 | H12: 24 | I12: =IFERROR((G12-H12)/G12,0) | J12: All entry | K12: All day
A13: 12 | B13: GLOW UP | C13: UNSTOPPABLE GLOW | D13: Smoothie | E13: 16oz | F13: Strawberry (frozen) 105g + Banana (frozen) 75g + Beetroot Powder 1.5tsp + Date 22g + Oat Milk 180ml | G13: 108 | H13: 51 | I13: =IFERROR((G13-H13)/G13,0) | J13: Wellness Mom | K13: All day
... A24: 23 | B24: COOL WAVE | C24: SUMMER SERENITY | D24: Smoothie | E24: 16oz | F24: Watermelon (frozen) 150g + Watermelon (fresh) 100g + Strawberry (frozen) 30g + Coconut water 30ml + Lime juice + Lemon zest + Mint | G24: 98 | H24: 22 | I24: =IFERROR((G24-H24)/G24,0) | J24: Tourist, All | K24: All day
A25: 24 | B25: GREEN GO | C25: DAILY ESCAPE | D25: Wrap Plant | E25: 8" | F25: Tortilla 8" + Hummus 25g + Roasted veg 50g + Spinach + Cucumber + Tomato + Tahini | G25: 99 | H25: 22 | I25: =IFERROR((G24-H24)/G24,0) | J25: Wellness, Vegan | K25: Lunch
A26: 25 | B26: POWER UP | C26: PURE STRENGTH | D26: Wrap Chicken | E26: 8" | F26: Tortilla 8" + Grilled chicken 60g + Romaine + Tomato + Cucumber + Pesto-yogurt | G26: 99 | H26: 29 | I26: =IFERROR((G25-H25)/G25,0) | J26: Office Nut, Fitness | K26: Lunch
A27: 26 | B27: RIDE FRESH | C27: OCEAN LIFE | D27: Wrap Tuna | E27: 8" | F27: Tortilla 8" + Tuna 40g + Mixed greens + Tomato + Olives + Lemon-mustard | G27: 99 | H27: 37 | I27: =IFERROR((G26-H26)/G26,0) | J27: Office Nut | K27: Lunch
A28: 27 | B28: TASTE HOME | C28: ASIAN HUG | D28: Wrap Thai | E28: 8" | F28: Tortilla 8" + Thai chicken 50g + Greens + Pomelo + Thai herbs + Spicy Thai dressing | G28: 99 | H28: 33 | I28: =IFERROR((G27-H27)/G27,0) | J28: Tourist, Local | K28: All day
A30: Add-ons + Shots
B31: + Whey Protein 25g | G31: 28 | H31: 12 | J31: Pair: HIGH VIBE, TOP FORM
B32: + Collagen 5g | G32: 25 | H32: 10 | J32: Pair: GLOW UP, SMILE ON
B33: + MCT Oil 5ml | G33: 28 | H33: 12 | J33: Pair: KEEP RISING
B34: + Spirulina 3g | G34: 18 | H34: 8 | J34: Pair: MIND CLEAR, RESET DAY
B35: + Avocado extra (wrap) | G35: 25 | H35: 8 | J35: Wrap upgrade
B36: + Extra Chicken (wrap) | G36: 25 | H36: 11 | J36: Wrap upgrade
B37: Olive Oil drizzle | G37: 0 | H37: 0 | J37: FREE — Better DNA on cold-press
B38: Ginger Shot 50ml | G38: 58 | H38: 18 | J38: Standalone wellness shot
B39: Kid's Classic 8oz | G39: 68 | H39: 22 | J39: Family menu

Sheet 🍎 Cold Press Matrix
A1: 🍎 BETTER JUICE · Cold-Press Recipe Matrix · ปริมาณส่วนผสม (g / ใบ / ลูก)
A2: เมนู | B2: 🍎 แอปเปิ้ลแดง Red Apple | C2: 🍏 แอปเปิ้ลเขียว Green Apple | D2: 🥕 แครอท Carrot | E2: 🍊 ส้ม Orange | F2: 🍍 สับปะรด Pineapple | G2: 🍉 แตงโม Watermelon | H2: 🥒 แตงกวา Cucumber | I2: 🌸 เสาวรส Passion Fruit | J2: 🍋 เลมอน Lemon | K2: 🟢 มะนาว Lime | L2: 🌿 ขิงสด Ginger | M2: 🌱 ขึ้นฉ่าย Celery | N2: 🥬 เคล Kale | O2: 🫀 บีทรูท Beetroot | P2: 🍈 ฝรั่ง Guava | Q2: 🟣 ทับทิม Pomegranate | R2: 🌿 สะระแหน่ Mint | S2: 🌿 โหระพา Sweet Basil | T2: 🧂 เกลือ Sea Salt
A3: #1 KEEP RISING | B3: 225 g | C3: – | D3: 96 g | E3: – | F3: – | G3: – | H3: – | I3: – | J3: – | K3: 8 g | L3: 3 g | M3: – | N3: – | O3: – | P3: – | Q3: – | R3: – | S3: – | T3: 1 หยิบมือ
A4: #2 MIND CLEAR | B4: – | C4: – | D4: – | E4: – | F4: 168 g | G4: – | H4: 144 g | I4: – | J4: – | K4: ¼ ลูก | L4: 2.4 g | M4: 24 g | N4: 20 g | O4: – | P4: – | Q4: – | R4: – | S4: – | T4: –
A5: #3 SMILE ON | B5: – | C5: – | D5: 75 g | E5: 245 g | F5: – | G5: – | H5: – | I5: 55 g | J5: – | K5: – | L5: – | M5: 30 g | N5: – | O5: – | P5: – | Q5: – | R5: – | S5: – | T5: 1 หยิบมือ
A6: #4 FULL POWER | B6: – | C6: – | D6: – | E6: – | F6: 75 g | G6: 190 g | H6: – | I6: 30 g | J6: – | K6: ¼ ลูก | L6: – | M6: – | N6: – | O6: – | P6: – | Q6: – | R6: 2 ใบ | S6: – | T6: 1 หยิบมือ
A7: #5 KEEP GOING | B7: 180 g | C7: – | D7: 220 g | E7: – | F7: – | G7: – | H7: – | I7: – | J7: 24 g | K7: – | L7: – | M7: – | N7: – | O7: 18 g | P7: – | Q7: – | R7: – | S7: – | T7: –
A8: #6 RESET DAY | B8: – | C8: 200 g | D8: – | E8: – | F8: 90 g | G8: – | H8: – | I8: – | J8: – | K8: ¼ ลูก | L8: – | M8: 45 g | N8: – | O8: – | P8: – | Q8: – | R8: – | S8: 2 ใบ | T8: –
A9: #7 STAY SHARP | B9: – | C9: 140 g | D9: – | E9: – | F9: – | G9: – | H9: 140 g | I9: – | J9: 7 g | K9: – | L9: – | M9: 18 g | N9: 8 g | O9: – | P9: – | Q9: – | R9: 3–4 ใบ | S9: – | T9: –
A10: #8 EASY FLOW | B10: 100 g | C10: 44 g | D10: – | E10: – | F10: – | G10: – | H10: – | I10: – | J10: – | K10: ¼ ลูก | L10: – | M10: – | N10: – | O10: – | P10: 165 g | Q10: – | R10: – | S10: – | T10: 2 หยิบมือ
A11: #9 SHINE BRIGHT | B11: 90 g | C11: – | D11: – | E11: 160 g | F11: 110 g | G11: – | H11: – | I11: – | J11: – | K11: – | L11: 5 g | M11: – | N11: – | O11: 50 g | P11: – | Q11: – | R11: – | S11: – | T11: –
A12: #10 STAND PROUD | B12: – | C12: 80 g | D12: 50 g | E12: – | F12: – | G12: – | H12: – | I12: – | J12: ⅛ ลูก | K12: – | L12: – | M12: – | N12: – | O12: – | P12: – | Q12: 180 g | R12: 2–3 ใบ | S12: – | T12: –
A14: หมายเหตุ: ปริมาณข้างต้นเป็นต่อแก้ว (12 oz) · น้ำแข็ง + Cup ไม่แสดงในตาราง · '–' = ไม่ใช้ส่วนผสมนี้

Sheet 🧾 Ingredient List
A1: 🧾 BETTER JUICE — INGREDIENT LIST · จ่ายตลาด + รับเข้า (2-Week Launch: 28 พ.ค. – 10 มิ.ย. 2026)
A2: 8 หมวด · ❄️ GLOW UP ×1.5 (Strawberry 105g · Banana 75g · Oat Milk 180ml) · GO GREEN ×1.4 (Kale Powder 1.5tsp · Coconut Water 140ml) · กรอก Receiving Log ทุกครั้งรับสินค้า
A3: # | B3: วัตถุดิบ | C3: หมวดหมู่ | D3: หน่วย | E3: Net 2wk | F3: Buffer % | G3: ปริมาณสั่ง (incl. buffer) | H3: ซื้อทุก | I3: ราคา/หน่วย ฿ | J3: รวม 2wk ฿ | K3: Supplier | L3: SKU ที่ใช้
A4: 🍎 ผลไม้สด
A5: 1 | B5: Apple (Red / Fuji) | C5: 🍎 ผลไม้สด | D5: kg | E5: 18.5 | F5: 15% | G5: 21.3 | H5: ทุกวัน | I5: 55 | J5: 1172 | K5: ตลาดอยุธยา | L5: KEEP RISING, KEEP GOING, EASY FLOW, SHINE BRIGHT
A6: 2 | B6: Green Apple (สด) | C6: 🍎 ผลไม้สด | D6: kg | E6: 7.5 | F6: 15% | G6: 8.6 | H6: ทุกวัน | I6: 60 | J6: 516 | K6: ตลาดอยุธยา | L6: RESET DAY, STAY SHARP, EASY FLOW, STAND PROUD
A7: 3 | B7: Orange | C7: 🍎 ผลไม้สด | D7: kg | E7: 14 | F7: 15% | G7: 16.1 | H7: ทุกวัน | I7: 45 | J7: 725 | K7: ตลาดอยุธยา | L7: SMILE ON, SHINE BRIGHT
A8: 4 | B8: Pineapple (สด) | C8: 🍎 ผลไม้สด | D8: kg | E8: 7.5 | F8: 10% | G8: 8.2 | H8: ทุกวัน | I8: 45 | J8: 369 | K8: ตลาดอยุธยา | L8: MIND CLEAR, FULL POWER, RESET DAY, SHINE BRIGHT (cold-press)
A9: 5 | B9: Watermelon (สด) | C9: 🍎 ผลไม้สด | D9: kg | E9: 9.5 | F9: 10% | G9: 10.5 | H9: 2×/สัปดาห์ | I9: 20 | J9: 210 | K9: ตลาดอยุธยา | L9: FULL POWER (cold-press) · COOL WAVE 100g/cup
A10: 6 | B10: Passion Fruit (สด) | C10: 🍎 ผลไม้สด | D10: kg | E10: 2.5 | F10: 15% | G10: 2.9 | H10: 2×/สัปดาห์ | I10: 90 | J10: 261 | K10: ตลาดอยุธยา | L10: SMILE ON, FULL POWER (cold-press)
A11: 7 | B11: Lime (มะนาว) | C11: 🍎 ผลไม้สด | D11: kg | E11: 4.2 | F11: 15% | G11: 4.8 | H11: ทุกวัน | I11: 35 | J11: 168 | K11: ตลาดอยุธยา | L11: หลายเมนู · COOL WAVE
A12: 8 | B12: Lemon (เลมอน) | C12: 🍎 ผลไม้สด | D12: kg | E12: 1.2 | F12: 15% | G12: 1.4 | H12: 2×/สัปดาห์ | I12: 70 | J12: 98 | K12: ตลาดอยุธยา | L12: KEEP GOING, STAY SHARP, STAND PROUD · COOL WAVE zest
A13: 9 | B13: Guava (ฝรั่ง สด) | C13: 🍎 ผลไม้สด | D13: kg | E13: 1 | F13: 10% | G13: 1.1 | H13: 2×/สัปดาห์ | I13: 40 | J13: 44 | K13: ตลาดอยุธยา | L13: EASY FLOW (cold-press)
A14: 10 | B14: Avocado (สด) | C14: 🍎 ผลไม้สด | D14: kg | E14: 1 | F14: 10% | G14: 1.1 | H14: 2×/สัปดาห์ | I14: 200 | J14: 220 | K14: ตลาดไท / Import | L14: YOU DESERVE IT, PURE JOY — ใช้คู่กับเมนูแช่แข็ง
A15: 11 | B15: Pomegranate | C15: 🍎 ผลไม้สด | D15: kg | E15: 1 | F15: 10% | G15: 1.1 | H15: 1×/สัปดาห์ | I15: 180 | J15: 198 | K15: ตลาดอยุธยา | L15: STAND PROUD
A16: 12 | B16: Pomelo (ส้มโอ) | C16: 🍎 ผลไม้สด | D16: pcs | E16: 4 | F16: 10% | G16: 4.4 | H16: 1×/สัปดาห์ | I16: 30 | J16: 132 | K16: ตลาดอยุธยา | L16: TASTE HOME
A17: 🥬 ผักสด & สมุนไพร
A18: 13 | B18: Carrot (แครอท) | C18: 🥬 ผักสด & สมุนไพร | D18: kg | E18: 15.5 | F18: 15% | G18: 17.8 | H18: ทุกวัน | I18: 30 | J18: 534 | K18: ตลาดอยุธยา | L18: KEEP RISING, SMILE ON, KEEP GOING, STAND PROUD, TASTE HOME
A19: 14 | B19: Cucumber (แตงกวา) | C19: 🥬 ผักสด & สมุนไพร | D19: kg | E19: 9 | F19: 10% | G19: 9.9 | H19: ทุกวัน | I19: 30 | J19: 297 | K19: ตลาดอยุธยา | L19: MIND CLEAR, STAY SHARP, Wraps
A20: 15 | B20: Celery (ขึ้นฉ่าย) | C20: 🥬 ผักสด & สมุนไพร | D20: kg | E20: 3.5 | F20: 15% | G20: 4 | H20: 2×/สัปดาห์ | I20: 50 | J20: 200 | K20: ตลาดอยุธยา | L20: MIND CLEAR, SMILE ON, RESET DAY, STAY SHARP
A21: 16 | B21: Kale (ผักเคล) | C21: 🥬 ผักสด & สมุนไพร | D21: kg | E21: 1 | F21: 20% | G21: 1.2 | H21: 2×/สัปดาห์ | I21: 120 | J21: 144 | K21: ตลาดอยุธยา | L21: MIND CLEAR, STAY SHARP
A22: 17 | B22: Spinach (ผักโขม) | C22: 🥬 ผักสด & สมุนไพร | D22: kg | E22: 0.5 | F22: 20% | G22: 0.6 | H22: 2×/สัปดาห์ | I22: 80 | J22: 48 | K22: ตลาดอยุธยา | L22: THINK SHARP, STAY FRESH
A23: 18 | B23: Beetroot (หัวบีต) | C23: 🥬 ผักสด & สมุนไพร | D23: kg | E23: 1.2 | F23: 15% | G23: 1.4 | H23: 1×/สัปดาห์ | I23: 80 | J23: 112 | K23: ตลาดอยุธยา | L23: KEEP GOING, SHINE BRIGHT
A24: 19 | B24: Ginger (ขิง) | C24: 🥬 ผักสด & สมุนไพร | D24: kg | E24: 0.5 | F24: 20% | G24: 0.6 | H24: 2×/สัปดาห์ | I24: 60 | J24: 36 | K24: ตลาดอยุธยา | L24: KEEP RISING, MIND CLEAR, SHINE BRIGHT, THINK SHARP, WARM UP, Ginger Shot
A25: 20 | B25: Mint (สะระแหน่) | C25: 🥬 ผักสด & สมุนไพร | D25: bunch | E25: 10 | F25: 20% | G25: 12 | H25: 2×/สัปดาห์ | I25: 15 | J25: 180 | K25: ตลาดอยุธยา | L25: STAY SHARP, STAND PROUD · COOL WAVE 4 ใบ/cup
A26: 21 | B26: Sweet Basil (โหระพา) | C26: 🥬 ผักสด & สมุนไพร | D26: bunch | E26: 4 | F26: 20% | G26: 4.8 | H26: 2×/สัปดาห์ | I26: 15 | J26: 72 | K26: ตลาดอยุธยา | L26: RESET DAY
A27: 22 | B27: Romaine / Mixed Greens | C27: 🥬 ผักสด & สมุนไพร | D27: kg | E27: 1.5 | F27: 15% | G27: 1.7 | H27: ทุกวัน | I27: 60 | J27: 102 | K27: ตลาดอยุธยา | L27: Wraps ทุกประเภท
A28: 23 | B28: Tomato (มะเขือเทศ) | C28: 🥬 ผักสด & สมุนไพร | D28: kg | E28: 2 | F28: 10% | G28: 2.2 | H28: ทุกวัน | I28: 40 | J28: 88 | K28: ตลาดอยุธยา | L28: Wraps ทุกประเภท
A29: 24 | B29: Thai Herbs (ผักชี/โหระพา) | C29: 🥬 ผักสด & สมุนไพร | D29: bunch | E29: 6 | F29: 20% | G29: 7.2 | H29: 2×/สัปดาห์ | I29: 15 | J29: 108 | K29: ตลาดอยุธยา | L29: TASTE HOME
A30: ❄️ แช่แข็ง
A31: 25 | B31: Strawberry (แช่แข็ง) | C31: ❄️ แช่แข็ง | D31: kg | E31: 8.6 | F31: 10% | G31: 9.5 | H31: 1×/สัปดาห์ | I31: 160 | J31: 1520 | K31: ตลาดไท / Import | L31: FEEL GOOD, GLOW UP ×1.5 (105g), TOP FORM, GROW STRONG, WARM UP · COOL WAVE 30g/cup
A32: 26 | B32: Banana (แช่แข็ง) | C32: ❄️ แช่แข็ง | D32: kg | E32: 11.1 | F32: 10% | G32: 12.2 | H32: 2×/สัปดาห์ | I32: 25 | J32: 305 | K32: ตลาดอยุธยา → แช่เอง | L32: FEEL GOOD, GLOW UP ×1.5 (75g), YOU DESERVE IT, HIGH VIBE, THINK SHARP, GROW STRONG, GO GREEN ×1.4 (42g), PURE JOY
A33: 27 | B33: Mango (แช่แข็ง) | C33: ❄️ แช่แข็ง | D33: kg | E33: 4.9 | F33: 10% | G33: 5.4 | H33: 1×/สัปดาห์ | I33: 80 | J33: 432 | K33: ตลาดไท / Import | L33: TOP FORM, STAY SUNNY, GO GREEN
A34: 28 | B34: Watermelon (แช่แข็ง) | C34: ❄️ แช่แข็ง | D34: kg | E34: 3.8 | F34: 10% | G34: 4.2 | H34: 1×/สัปดาห์ | I34: 55 | J34: 231 | K34: ตลาดไท / Import | L34: COOL WAVE 150g/cup
A35: 29 | B35: Pineapple (แช่แข็ง) | C35: ❄️ แช่แข็ง | D35: kg | E35: 3.1 | F35: 10% | G35: 3.4 | H35: 1×/สัปดาห์ | I35: 60 | J35: 204 | K35: ตลาดไท / Import | L35: STAY SUNNY, GO GREEN, WARM UP
A36: 30 | B36: Passion Fruit Puree | C36: ❄️ แช่แข็ง | D36: kg | E36: 0.8 | F36: 10% | G36: 0.9 | H36: 1×/สัปดาห์ | I36: 180 | J36: 162 | K36: ตลาดไท / Import | L36: STAY SUNNY — topping / blend
A37: 31 | B37: Guava (แช่แข็ง) | C37: ❄️ แช่แข็ง | D37: kg | E37: 1 | F37: 10% | G37: 1.1 | H37: 1×/สัปดาห์ | I37: 80 | J37: 88 | K37: ตลาดไท / Import | L37: STAY FRESH (smoothie)
A38: 32 | B38: Green Apple (แช่แข็ง) | C38: ❄️ แช่แข็ง | D38: kg | E38: 0.5 | F38: 10% | G38: 0.6 | H38: 1×/สัปดาห์ | I38: 90 | J38: 54 | K38: ตลาดไท / Import | L38: STAY FRESH (smoothie)
A39: 33 | B39: Acai (แช่แข็ง) | C39: ❄️ แช่แข็ง | D39: kg | E39: 1 | F39: 10% | G39: 1.1 | H39: 1×/สัปดาห์ | I39: 350 | J39: 385 | K39: Import / ร้านสุขภาพ | L39: Future SKU / smoothie bowl
A40: 34 | B40: Raspberry (แช่แข็ง) | C40: ❄️ แช่แข็ง | D40: kg | E40: 0.5 | F40: 10% | G40: 0.6 | H40: 1×/สัปดาห์ | I40: 280 | J40: 168 | K40: Import / ตลาดไท | L40: HIGH VIBE
...

Sheet ✅ This Week
B2: ✅ This Week — Focus
B3: งานสัปดาห์นี้ · เช็คทุกเช้า 5 นาที · จันทร์ refresh
B5: # | C5: งาน | D5: เจ้าของ | E5: Due | F5: สถานะ | G5: หมายเหตุ
B6: ⭐ | C6: Brief Yu — supplier list ผัก/ผลไม้/มะพร้าว 2 รายต่อหมวด + tortilla BKK import | D6: CEO+Yu | E6: +3 วัน | F6: Not Started
B7: ⭐ | C7: Hire Juicer ×2 + Cashier ×1 — Store Mgr lead interview | D7: Store Mgr | E7: +5 วัน | F7: Not Started | G7: cross-train ทำ wrap
B8: ⭐ | C8: POS choice: Loyverse vs FoodStory + setup 26 SKU | D8: CEO | E8: +5 วัน | F8: Not Started
C9: Order whole wheat tortilla 8" BKK + test | D9: Yu | E9: +7 วัน | F9: Not Started | G9: 30 ใบ/วัน need
C10: Test 4 cold-press launch ตามกรัม Recipe Master Book v2 | D10: CEO+Yu | E10: +4 วัน | F10: Not Started | G10: KEEP RISING, MIND CLEAR, SMILE ON, FULL POWER
C11: Test 4 smoothie launch | D11: CEO+Yu | E11: +4 วัน | F11: Not Started | G11: FEEL GOOD, GLOW UP, YOU DESERVE IT, HIGH VIBE
C12: Mural + signage 'Fuel Your Better' ติดผนัง | D12: Designer | E12: +8 วัน | F12: Not Started
C13: ปริ้น recipe card 26 ใบ ติด counter | D13: Designer+CEO | E13: +10 วัน | F13: Not Started
C14: Soft Launch invitation copy + invite 30 คน (D-5 = 8 พ.ค.) | D14: CEO+Marketing | E14: +5 วัน | F14: Not Started
C15: Content batch 15 posts (Soft Launch period) | D15: Marketing | E15: +10 วัน | F15: Not Started | G15: Reels + carousel
C16: Setup LINE OA + Google Business + IG/TikTok account | D16: Marketing | E16: +3 วัน | F16: Not Started
C17: Cross-train ทีม wrap prep + sandwich press SOP | D17: Store Mgr | E17: +7 วัน | F17: Not Started
B20: 📅 Weekly Rhythm
B21: ทุกเช้า 08:30 | C21: เปิด This Week · ตัดสินใจ 1 เรื่อง
B22: ทุกเย็น 18:30 | C22: กรอก Daily Log (3 นาที)
B23: จันทร์ 09:00 | C23: Refresh This Week · ดู Home dashboard
B24: พุธ 10:00 | C24: Recipe R&D test 1-2 ตัว
B25: ศุกร์ 14:00 | C25: Content plan สัปดาห์หน้า
B26: วันที่ 5 ของเดือน | C26: P&L review + Suppliers scorecard
B27: ทุก 90 วัน | C27: Quarterly playbook review (กับ Claude)

Sheet 👥 Team
B2: 👥 Team
B3: พนักงาน + บทบาท · update เดือนละ 1
B5: ตำแหน่ง | C5: ชื่อ | D5: เริ่มงาน | E5: เงินเดือน ฿ | F5: สถานะ | G5: หมายเหตุ
B6: 👨‍💼 | C6: CEO / Founder | D6: Natthanan (Nut) | E6: — | F6: — | G6: Active | H6: Vision + decisions
B7: 👨‍💼 | C7: Business Dev | D7: Amornchai (Yu) | E7: — | F7: — | G7: Active | H7: Supplier + B2B
B8: 👤 | C8: Store Manager | D8: [ชื่อ] | E8: 1 พ.ค. 2026 | F8: 25000 | G8: Hired | H8: ✓ ปิดดีลแล้ว
B9: 👤 | C9: Juicer / Barista #1 | E9: +5 วัน | F9: 15000 | G9: Open | H9: ต้อง hire + cross-train wrap
B10: 👤 | C10: Juicer / Barista #2 | E10: +5 วัน | F10: 15000 | G10: Open | H10: ต้อง hire + cross-train wrap
B11: 👤 | C11: Cashier / Front | E11: +5 วัน | F11: 13000 | G11: Open | H11: เน้น communication
B12: 📷 | C12: Content Creator (PT) | E12: +7 วัน | F12: 10000 | G12: Open | H12: Freelance 2 วัน/สัปดาห์
B13: 👨‍🍳 | C13: Kitchen Helper | E13: Future | F13: 12000 | G13: Future | H13: พิจารณาอีกครั้ง D+30
C15: Total monthly payroll (Active+Hired): | F15: =SUMIFS(F6:F14,G6:G14,"Active")+SUMIFS(F6:F14,G6:G14,"Hired")

Sheet 🛒 Suppliers
B2: 🛒 Suppliers
B3: ผู้ขาย + คะแนน · review รายเดือน · ตัด supplier ที่ score < 80% 2 เดือนติด
B5: หมวด | C5: Tier | D5: Supplier | E5: เบอร์/ติดต่อ | F5: Quality 1-5 | G5: Reliability 1-5 | H5: Price 1-5 | I5: Score | J5: หมายเหตุ
B6: 🥬 | C6: ผัก/ผลไม้สด | D6: 1 | E6: [ตลาดอยุธยา รายใหญ่] | J6: =IFERROR(AVERAGE(G6:I6),0) | K6: Apple, Carrot, Orange 3-5kg/วัน
B7: 🥬 | C7: ผัก/ผลไม้สด | D7: 2 | E7: [Backup] | J7: =IFERROR(AVERAGE(G7:I7),0) | K7: ทดสอบ batch แรก
B8: 🥥 | C8: มะพร้าวอ่อน | D8: 1 | J8: =IFERROR(AVERAGE(G8:I8),0) | K8: PURE EDEN + NATURE BLISS 2-3L/วัน
B9: 🥥 | C9: มะพร้าวอ่อน | D9: 2 | J9: =IFERROR(AVERAGE(G9:I9),0)
B10: 🌿 | C10: Matcha grade A | D10: 1 | J10: =IFERROR(AVERAGE(G10:I10),0) | K10: THINK SHARP 200g/wk
B11: 🥛 | C11: นมพืช (oat/almond) | D11: 1 | J11: =IFERROR(AVERAGE(G11:I11),0) | K11: 3-4 ลิตร/วัน
B12: 💪 | C12: Whey Protein | D12: 1 | J12: =IFERROR(AVERAGE(G12:I12),0) | K12: Add-on stock
B13: ✨ | C13: Collagen powder | D13: 1 | J13: =IFERROR(AVERAGE(G13:I13),0) | K13: Add-on
B14: 🥃 | C14: Cup, lid, straw | D14: 1 | J14: =IFERROR(AVERAGE(G14:I14),0) | K14: Logo print
B15: 📦 | C15: Sticker + Paper bag | D15: 1 | J15: =IFERROR(AVERAGE(G15:I15),0) | K15: Logo print
B16: 🌯 | C16: Whole Wheat Tortilla 8" | D16: 1 | E16: [Bangkok import] | J16: =IFERROR(AVERAGE(G16:I16),0) | K16: 30 ใบ/วัน Phase 1 → 60+ Phase 2 ✓ LOCKED
B17: 🍗 | C17: Grilled Chicken Breast | D17: 1 | J17: =IFERROR(AVERAGE(G17:I17),0) | K17: 1-2 kg/วัน · ไก่บ้านหรือทั่วไป
B18: 🐟 | C18: Tuna น้ำเปล่า (canned) | D18: 1 | J18: =IFERROR(AVERAGE(G18:I18),0) | K18: 5-8 cans/wk
B19: 🧂 | C19: Sea Salt + Pink Salt | D19: 1 | J19: =IFERROR(AVERAGE(G19:I19),0) | K19: 1 kg/เดือน
B20: 🫒 | C20: Olive Oil (signature) | D20: 1 | J20: =IFERROR(AVERAGE(G20:I20),0) | K20: 1 ขวด/2 wk · Better DNA
